Workbook

Sheet Competencias_actuales
B1: Competencias actuales del laboratorio
A2: =VALUE(LEFT(F4,FIND(" - ",F4)-1)) -> 795
D3: Nombre del Curso | F3: =IFERROR(__xludf.DUMMYFUNCTION("VLOOKUP(A2,IMPORTRANGE(""1j2lHEvOoZ_EPY086Qt7f7AFaZGVfiYKJxXlsnNfWCA0"", ""Listado Cursos!$A$2:$H$100""),2,FALSE)"),"Logica de Sitemas") -> Logica de Sitemas
D4: Código del Curso | F4: 795 - Logica de Sitemas
D5: Semestre | F5: =IFERROR(__xludf.DUMMYFUNCTION("VLOOKUP(A2,IMPORTRANGE(""1j2lHEvOoZ_EPY086Qt7f7AFaZGVfiYKJxXlsnNfWCA0"", ""Listado Cursos!A:G""),4,FALSE)"),3.0) -> 3
D6: Área de Conocimiento | F6: =IFERROR(__xludf.DUMMYFUNCTION("VLOOKUP(A2,IMPORTRANGE(""1j2lHEvOoZ_EPY086Qt7f7AFaZGVfiYKJxXlsnNfWCA0"", ""Listado Cursos!A:G""),6,FALSE)"),"Sistemas") -> Sistemas
D7: Cantidad de Creditos | F7: =IFERROR(__xludf.DUMMYFUNCTION("VLOOKUP(A2,IMPORTRANGE(""1j2lHEvOoZ_EPY086Qt7f7AFaZGVfiYKJxXlsnNfWCA0"", ""Listado Cursos!A:G""),3,FALSE)"),3.0) -> 3
D8: Horas de aprendizaje | F8: 4
B11: Descripción del Contexto
B13: Que cursos prerrequisito tiene | F13: Cursos que lleva en el mismo semestre | J13: Qué cursos posteriores dependen de este
B14: No. | C14: Codigo | D14: Nombre | F14: No. | G14: Codigo | H14: Nombre | J14: No. | K14: Codigo | L14: Nombre
B15: 1 | C15: =IFERROR(__xludf.DUMMYFUNCTION("ARRAYFORMULA(TRANSPOSE(SPLIT(FILTER(IMPORTRANGE(""1j2lHEvOoZ_EPY086Qt7f7AFaZGVfiYKJxXlsnNfWCA0"", ""Listado Cursos!E:E""), IMPORTRANGE(""1j2lHEvOoZ_EPY086Qt7f7AFaZGVfiYKJxXlsnNfWCA0"", ""Listado Cursos!A:A"")=A2), "","")))"),103.0) -> 103 | D15: =IFERROR(__xludf.DUMMYFUNCTION("IF(C15="""","""",VLOOKUP(C15,IMPORTRANGE(""1j2lHEvOoZ_EPY086Qt7f7AFaZGVfiYKJxXlsnNfWCA0"", ""Listado Cursos!A:B""),2,FALSE))"),"Área Matemática Básica 2") -> Área Matemática Básica 2 | F15: 1 | G15: =IFERROR(__xludf.DUMMYFUNCTION("FILTER(IMPORTRANGE(""1j2lHEvOoZ_EPY086Qt7f7AFaZGVfiYKJxXlsnNfWCA0"", ""Listado Cursos!A:B""),IMPORTRANGE(""1j2lHEvOoZ_EPY086Qt7f7AFaZGVfiYKJxXlsnNfWCA0"", ""Listado Cursos!D:D"")=F5,IMPORTRANGE(""1j2lHEvOoZ_EPY086Qt7f7AFaZGVfiYKJxXlsnNfWCA0"", ""Listado C"&"ursos!A:A"")<>150)"),795.0) -> 795 | H15: =IFERROR(__xludf.DUMMYFUNCTION("""COMPUTED_VALUE"""),"Logica de Sitemas") -> Logica de Sitemas | J15: 1 | K15: =IFERROR(__xludf.DUMMYFUNCTION("FILTER(IMPORTRANGE(""1j2lHEvOoZ_EPY086Qt7f7AFaZGVfiYKJxXlsnNfWCA0"", ""Listado Cursos!A:B""), ISNUMBER(SEARCH(A2, IMPORTRANGE(""1j2lHEvOoZ_EPY086Qt7f7AFaZGVfiYKJxXlsnNfWCA0"", ""Listado Cursos!E:E""))))"),796.0) -> 796 | L15: =IFERROR(__xludf.DUMMYFUNCTION("""COMPUTED_VALUE"""),"Lenguajes Formales y de Programación") -> Lenguajes Formales y de Programación
B16: 2 | C16: =IFERROR(__xludf.DUMMYFUNCTION("""COMPUTED_VALUE"""),147.0) -> 147 | D16: =IFERROR(__xludf.DUMMYFUNCTION("IF(C16="""","""",VLOOKUP(C16,IMPORTRANGE(""1j2lHEvOoZ_EPY086Qt7f7AFaZGVfiYKJxXlsnNfWCA0"", ""Listado Cursos!A:B""),2,FALSE))"),"Física Básica") -> Física Básica | F16: 2 | G16: =IFERROR(__xludf.DUMMYFUNCTION("""COMPUTED_VALUE"""),962.0) -> 962 | H16: =IFERROR(__xludf.DUMMYFUNCTION("""COMPUTED_VALUE"""),"Matemática Para Computación 2") -> Matemática Para Computación 2 | J16: 2 | K16: =IFERROR(__xludf.DUMMYFUNCTION("""COMPUTED_VALUE"""),771.0) -> 771 | L16: =IFERROR(__xludf.DUMMYFUNCTION("""COMPUTED_VALUE"""),"Introducción a la Programación y Computación 2") -> Introducción a la Programación y Computación 2
B17: 3 | C17: =IFERROR(__xludf.DUMMYFUNCTION("""COMPUTED_VALUE"""),960.0) -> 960 | D17: =IFERROR(__xludf.DUMMYFUNCTION("IF(C17="""","""",VLOOKUP(C17,IMPORTRANGE(""1j2lHEvOoZ_EPY086Qt7f7AFaZGVfiYKJxXlsnNfWCA0"", ""Listado Cursos!A:B""),2,FALSE))"),"Matemática Para Computación 1") -> Matemática Para Computación 1 | F17: 3 | G17: =IFERROR(__xludf.DUMMYFUNCTION("""COMPUTED_VALUE"""),770.0) -> 770 | H17: =IFERROR(__xludf.DUMMYFUNCTION("""COMPUTED_VALUE"""),"Introducción a ala programación y computación 1") -> Introducción a ala programación y computación 1 | J17: 3
B18: 4 | D18: =IFERROR(__xludf.DUMMYFUNCTION("IF(C18="""","""",VLOOKUP(C18,IMPORTRANGE(""1j2lHEvOoZ_EPY086Qt7f7AFaZGVfiYKJxXlsnNfWCA0"", ""Listado Cursos!A:B""),2,FALSE))"),"") | F18: 4 | G18: =IFERROR(__xludf.DUMMYFUNCTION("""COMPUTED_VALUE"""),107.0) -> 107 | H18: =IFERROR(__xludf.DUMMYFUNCTION("""COMPUTED_VALUE"""),"Área Matemática Intermedia 1") -> Área Matemática Intermedia 1 | J18: 4
B19: 5 | D19: =IFERROR(__xludf.DUMMYFUNCTION("IF(C19="""","""",VLOOKUP(C19,IMPORTRANGE(""1j2lHEvOoZ_EPY086Qt7f7AFaZGVfiYKJxXlsnNfWCA0"", ""Listado Cursos!A:B""),2,FALSE))"),"") | F19: 5 | G19: =IFERROR(__xludf.DUMMYFUNCTION("""COMPUTED_VALUE"""),1.0) -> 1 | H19: =IFERROR(__xludf.DUMMYFUNCTION("""COMPUTED_VALUE"""),"Ética Profesional") -> Ética Profesional | J19: 5
B20: 6 | D20: =IFERROR(__xludf.DUMMYFUNCTION("IF(C20="""","""",VLOOKUP(C20,IMPORTRANGE(""1j2lHEvOoZ_EPY086Qt7f7AFaZGVfiYKJxXlsnNfWCA0"", ""Listado Cursos!A:B""),2,FALSE))"),"") | F20: 6 | G20: =IFERROR(__xludf.DUMMYFUNCTION("""COMPUTED_VALUE"""),9.0) -> 9 | H20: =IFERROR(__xludf.DUMMYFUNCTION("""COMPUTED_VALUE"""),"Idioma Técnico 3") -> Idioma Técnico 3 | J20: 6
B21: 7 | D21: =IFERROR(__xludf.DUMMYFUNCTION("IF(C21="""","""",VLOOKUP(C21,IMPORTRANGE(""1j2lHEvOoZ_EPY086Qt7f7AFaZGVfiYKJxXlsnNfWCA0"", ""Listado Cursos!A:B""),2,FALSE))"),"") | F21: 7 | G21: =IFERROR(__xludf.DUMMYFUNCTION("""COMPUTED_VALUE"""),92.0) -> 92 | H21: =IFERROR(__xludf.DUMMYFUNCTION("""COMPUTED_VALUE"""),"Programacion de Computadoras 2") -> Programacion de Computadoras 2 | J21: 7
B22: 8 | D22: =IFERROR(__xludf.DUMMYFUNCTION("IF(C22="""","""",VLOOKUP(C22,IMPORTRANGE(""1j2lHEvOoZ_EPY086Qt7f7AFaZGVfiYKJxXlsnNfWCA0"", ""Listado Cursos!A:B""),2,FALSE))"),"") | F22: 8 | G22: =IFERROR(__xludf.DUMMYFUNCTION("""COMPUTED_VALUE"""),89.0) -> 89 | H22: =IFERROR(__xludf.DUMMYFUNCTION("""COMPUTED_VALUE"""),"Comunicación Asertiva") -> Comunicación Asertiva | J22: 8
B23: 9 | D23: =IFERROR(__xludf.DUMMYFUNCTION("IF(C23="""","""",VLOOKUP(C23,IMPORTRANGE(""1j2lHEvOoZ_EPY086Qt7f7AFaZGVfiYKJxXlsnNfWCA0"", ""Listado Cursos!A:B""),2,FALSE))"),"") | F23: 9 | J23: 9
B24: 10 | D24: =IFERROR(__xludf.DUMMYFUNCTION("IF(C24="""","""",VLOOKUP(C24,IMPORTRANGE(""1j2lHEvOoZ_EPY086Qt7f7AFaZGVfiYKJxXlsnNfWCA0"", ""Listado Cursos!A:B""),2,FALSE))"),"") | F24: 10 | J24: 10
B25: 11 | D25: =IFERROR(__xludf.DUMMYFUNCTION("IF(C25="""","""",VLOOKUP(C25,IMPORTRANGE(""1j2lHEvOoZ_EPY086Qt7f7AFaZGVfiYKJxXlsnNfWCA0"", ""Listado Cursos!A:B""),2,FALSE))"),"") | F25: 11 | J25: 11
B26: 12 | D26: =IFERROR(__xludf.DUMMYFUNCTION("IF(C26="""","""",VLOOKUP(C26,IMPORTRANGE(""1j2lHEvOoZ_EPY086Qt7f7AFaZGVfiYKJxXlsnNfWCA0"", ""Listado Cursos!A:B""),2,FALSE))"),"") | F26: 12 | J26: 12
B27: 13 | D27: =IFERROR(__xludf.DUMMYFUNCTION("IF(C27="""","""",VLOOKUP(C27,IMPORTRANGE(""1j2lHEvOoZ_EPY086Qt7f7AFaZGVfiYKJxXlsnNfWCA0"", ""Listado Cursos!A:B""),2,FALSE))"),"") | F27: 13 | J27: 13
B28: 14 | D28: =IFERROR(__xludf.DUMMYFUNCTION("IF(C28="""","""",VLOOKUP(C28,IMPORTRANGE(""1j2lHEvOoZ_EPY086Qt7f7AFaZGVfiYKJxXlsnNfWCA0"", ""Listado Cursos!A:B""),2,FALSE))"),"") | F28: 14 | J28: 14
B31: Competencias Actuales
B33: No. | C33: Tipo | D33: Competencia | L33: Nivel de la Taxonomina
B34: =IFERROR(__xludf.DUMMYFUNCTION("FILTER(METADA!D2:D17, ISEVEN(ROW(METADA!D2:D17)))"),1.0) -> 1 | C34: =IFERROR(__xludf.DUMMYFUNCTION("FILTER(METADA!E2:E17, ISEVEN(ROW(METADA!E2:E17)))"),"Especifica") -> Especifica | D34: =IFERROR(__xludf.DUMMYFUNCTION("FILTER(METADA!E2:E17, ISODD(ROW(METADA!E2:E17)))"),"Identifica los tipos de bloqueos mentales mediante el análisis de casos y experiencias personales en situaciones que dificultan la resolución de problemas ") -> Identifica los tipos de bloqueos mentales mediante el análisis de casos y experiencias personales en situaciones que dificultan la resolución de problemas | L34: =IFERROR(__xludf.DUMMYFUNCTION("FILTER(METADA!L2:L17, ISEVEN(ROW(METADA!L2:L17)))"),"Recordar") -> Recordar
B35: =IFERROR(__xludf.DUMMYFUNCTION("""COMPUTED_VALUE"""),2.0) -> 2 | C35: =IFERROR(__xludf.DUMMYFUNCTION("""COMPUTED_VALUE"""),"Especifica") -> Especifica | D35: =IFERROR(__xludf.DUMMYFUNCTION("""COMPUTED_VALUE"""),"Define las diferencias entre lógica formal, matemática y sistémica con base en ejemplos prácticos y ejercicios comparativos dentro de contextos académicos del curso ") -> Define las diferencias entre lógica formal, matemática y sistémica con base en ejemplos prácticos y ejercicios comparativos dentro de contextos académicos del curso | L35: =IFERROR(__xludf.DUMMYFUNCTION("""COMPUTED_VALUE"""),"Comprensión") -> Comprensión
B36: =IFERROR(__xludf.DUMMYFUNCTION("""COMPUTED_VALUE"""),3.0) -> 3 | C36: =IFERROR(__xludf.DUMMYFUNCTION("""COMPUTED_VALUE"""),"Especifica") -> Especifica | D36: =IFERROR(__xludf.DUMMYFUNCTION("""COMPUTED_VALUE"""),"Construye árboles lógicos y tríadas de conceptos utilizando los contenidos desarrollados durante el curso para representar estructuras lógicas de pensamiento ") -> Construye árboles lógicos y tríadas de conceptos utilizando los contenidos desarrollados durante el curso para representar estructuras lógicas de pensamiento | L36: =IFERROR(__xludf.DUMMYFUNCTION("""COMPUTED_VALUE"""),"Crear") -> Crear
B37: =IFERROR(__xludf.DUMMYFUNCTION("""COMPUTED_VALUE"""),4.0) -> 4 | C37: =IFERROR(__xludf.DUMMYFUNCTION("""COMPUTED_VALUE"""),"Especifica") -> Especifica | D37: =IFERROR(__xludf.DUMMYFUNCTION("""COMPUTED_VALUE"""),"Reconoce proposiciones y razonamientos en el lenguaje por medio del análisis de textos y enunciados para distinguir los componentes lógicos del lenguaje ") -> Reconoce proposiciones y razonamientos en el lenguaje por medio del análisis de textos y enunciados para distinguir los componentes lógicos del lenguaje | L37: =IFERROR(__xludf.DUMMYFUNCTION("""COMPUTED_VALUE"""),"Recordar") -> Recordar
B38: =IFERROR(__xludf.DUMMYFUNCTION("""COMPUTED_VALUE"""),5.0) -> 5 | C38: =IFERROR(__xludf.DUMMYFUNCTION("""COMPUTED_VALUE"""),"Especifica") -> Especifica | D38: =IFERROR(__xludf.DUMMYFUNCTION("""COMPUTED_VALUE"""),"Evalua razonamientos y falacias utilizando ejercicios escritos y discusiones dirigidas en la resolución de dilemas lógicos ") -> Evalua razonamientos y falacias utilizando ejercicios escritos y discusiones dirigidas en la resolución de dilemas lógicos | L38: =IFERROR(__xludf.DUMMYFUNCTION("""COMPUTED_VALUE"""),"Evaluar") -> Evaluar
B39: =IFERROR(__xludf.DUMMYFUNCTION("""COMPUTED_VALUE"""),6.0) -> 6 | C39: =IFERROR(__xludf.DUMMYFUNCTION("""COMPUTED_VALUE"""),"General") -> General | D39: =IFERROR(__xludf.DUMMYFUNCTION("""COMPUTED_VALUE"""),"Comprende los modelos mentales y paradigmas mediante el análisis de ejemplos y situaciones cotidianas en actividades de reflexión y discusión grupal ") -> Comprende los modelos mentales y paradigmas mediante el análisis de ejemplos y situaciones cotidianas en actividades de reflexión y discusión grupal | L39: =IFERROR(__xludf.DUMMYFUNCTION("""COMPUTED_VALUE"""),"Comprensión") -> Comprensión
B40: =IFERROR(__xludf.DUMMYFUNCTION("""COMPUTED_VALUE"""),7.0) -> 7 | C40: =IFERROR(__xludf.DUMMYFUNCTION("""COMPUTED_VALUE"""),"Especifica") -> Especifica | D40: =IFERROR(__xludf.DUMMYFUNCTION("""COMPUTED_VALUE"""),"Reconoce los principios fundamentales de la lógica mediante el análisis de enunciados y situaciones cotidianas que permitan desarrollar habilidades de pensamiento crítico y razonamiento válido") -> Reconoce los principios fundamentales de la lógica mediante el análisis de enunciados y situaciones cotidianas que permitan desarrollar habilidades de pensamiento crítico y razonamiento válido

Sheet Referentes Internacionales
B1: Identificación de referentes internacionales
B3: Nombre del Curso | C3: =Competencias_actuales!F3 -> Logica de Sitemas
B4: Codigo del Curso | C4: 795
B6: 1. Universidad Refente
B7: Analiza cursos similares en universidades internacionales reconocidas (como MIT, Stanford o ETH Zurich) para comparar temas, herramientas y competencias. Esto permite identificar buenas prácticas y alinear el laboratorio con tendencias globales en educación tecnológica.
B9: Nombre de la Universidad | C9: Brown University
B10: Nombre del Curso | C10: Logica para sistemas
B11: Fuente de Información | C11: https://cs.brown.edu/courses/
B13: Temas relacionados al laboratorio que se imparte
B14: Modelado con lógica -> Unidad 3 y 4 Especificación y razonamiento sobre sistemas -> Unidad 4 y 5
B17: Herramientas utilizadas relacionados al laboratorio que se imparte
B18: Arboles logicos
B21: Competencia(s) relacionada(s) al laboratorio que se imparte
B22: - Comprende las diferencias entre lógica formal, matemática y sistémica a través del análisis comparativo en ejercicios y situaciones académicas - Analiza proposiciones y razonamientos en el lenguaje identificando premisas, conclusiones y sus relaciones lógicas dentro de textos y enunciados
B26: 2. Estandar Internacional
B27: Se identifican estándares internacionales relevantes (como ABET, CDIO o IEEE/ACM) para verificar si el laboratorio cumple con criterios de calidad educativa, competencias clave y buenas prácticas recomendadas a nivel global.
B29: Nombre del Estandar | C29: ABET
B30: Sección , Capitulo , etc, | C30: General Criterion 3: Student Outcomes (apartados 1–6)
B31: Funte de Información | C31: https://www.abet.org/wp-content/uploads/2023/05/C001_CAC-Criteria_2023-2024.pdf
B33: Contenidos relacionados al laboratorio que se imparte
B34: - Lógica proposicional, tablas de verdad, razonamiento válido - Creatividad y paradigmas como habilidades transversales
B37: Nombre del Estandar | C37: ACM/IEEE Computer Science Curricula 2013
B38: Sección , Capitulo , etc, | C38: - Discrete Structures (DS) – DS1: Logic and Proofs - Discrete Structures (DS) – DS2: Boolean Algebra, Propositional Logic - Software Engineering (SE) – Modeling and Verification - Professional Practice (SP) – Problem Solving, Critical Thinking
B39: Funte de Información | C39: https://www.acm.org/education/curricula-recommendations
B41: Contenidos relacionados al laboratorio que se imparte
B42: - Lógica proposicional, tablas de verdad, razonamiento válido - Desarrollo de pensamiento crítico y creativo

Sheet TCO_vrs_Referentes
B1: Comparación con referentes internacionales
A2: =C4&" - "&C3 -> 795 - Logica de Sitemas
B3: Nombre del Curso | C3: =Competencias_actuales!F3 -> Logica de Sitemas
B4: Codigo del Curso | C4: =Competencias_actuales!A2 -> 795
B6: Laboratorio Actual | F6: Universidad Referente | G6: Estandar Referente
B7: Competencia | C7: Unidad | D7: Tema | E7: SubTema | F7: Presente en el referente (Sí/No) | G7: Presente en el referente (Sí/No)
B8: =IFERROR(__xludf.DUMMYFUNCTION("QUERY(IMPORTRANGE(VLOOKUP(A2,METADA!A:B,2,FALSE), ""Diseño Curricular!B4:E500""), )"),"Identifica los tipos de bloqueos mentales mediante el análisis de casos y experiencias personales en situaciones que dificultan la resolución de problemas ") -> Identifica los tipos de bloqueos mentales mediante el análisis de casos y experiencias personales en situaciones que dificultan la resolución de problemas | C8: =IFERROR(__xludf.DUMMYFUNCTION("""COMPUTED_VALUE"""),"Unidad 1: La creatividad y bloqueos mentales") -> Unidad 1: La creatividad y bloqueos mentales | D8: =IFERROR(__xludf.DUMMYFUNCTION("""COMPUTED_VALUE"""),"La creatividad") -> La creatividad | E8: =IFERROR(__xludf.DUMMYFUNCTION("""COMPUTED_VALUE"""),"¿Qué es la creatividad?") -> ¿Qué es la creatividad? | F8: No | G8: Sí
B9: =IFERROR(__xludf.DUMMYFUNCTION("""COMPUTED_VALUE"""),"Identifica los tipos de bloqueos mentales mediante el análisis de casos y experiencias personales en situaciones que dificultan la resolución de problemas ") -> Identifica los tipos de bloqueos mentales mediante el análisis de casos y experiencias personales en situaciones que dificultan la resolución de problemas | C9: =IFERROR(__xludf.DUMMYFUNCTION("""COMPUTED_VALUE"""),"Unidad 1: La creatividad y bloqueos mentales") -> Unidad 1: La creatividad y bloqueos mentales | D9: =IFERROR(__xludf.DUMMYFUNCTION("""COMPUTED_VALUE"""),"La creatividad") -> La creatividad | E9: =IFERROR(__xludf.DUMMYFUNCTION("""COMPUTED_VALUE"""),"Pasos en la resolución de problemas") -> Pasos en la resolución de problemas | F9: No | G9: Sí
B10: =IFERROR(__xludf.DUMMYFUNCTION("""COMPUTED_VALUE"""),"Identifica los tipos de bloqueos mentales mediante el análisis de casos y experiencias personales en situaciones que dificultan la resolución de problemas ") -> Identifica los tipos de bloqueos mentales mediante el análisis de casos y experiencias personales en situaciones que dificultan la resolución de problemas | C10: =IFERROR(__xludf.DUMMYFUNCTION("""COMPUTED_VALUE"""),"Unidad 1: La creatividad y bloqueos mentales") -> Unidad 1: La creatividad y bloqueos mentales | D10: =IFERROR(__xludf.DUMMYFUNCTION("""COMPUTED_VALUE"""),"La creatividad") -> La creatividad | E10: =IFERROR(__xludf.DUMMYFUNCTION("""COMPUTED_VALUE"""),"Bloqueos mentales") -> Bloqueos mentales | F10: No | G10: Sí
B11: =IFERROR(__xludf.DUMMYFUNCTION("""COMPUTED_VALUE"""),"Identifica los tipos de bloqueos mentales mediante el análisis de casos y experiencias personales en situaciones que dificultan la resolución de problemas ") -> Identifica los tipos de bloqueos mentales mediante el análisis de casos y experiencias personales en situaciones que dificultan la resolución de problemas | C11: =IFERROR(__xludf.DUMMYFUNCTION("""COMPUTED_VALUE"""),"Unidad 1: La creatividad y bloqueos mentales") -> Unidad 1: La creatividad y bloqueos mentales | D11: =IFERROR(__xludf.DUMMYFUNCTION("""COMPUTED_VALUE"""),"La creatividad") -> La creatividad | E11: =IFERROR(__xludf.DUMMYFUNCTION("""COMPUTED_VALUE"""),"Práctica de la creatividad") -> Práctica de la creatividad | F11: No | G11: Sí
B12: =IFERROR(__xludf.DUMMYFUNCTION("""COMPUTED_VALUE"""),"Identifica los tipos de bloqueos mentales mediante el análisis de casos y experiencias personales en situaciones que dificultan la resolución de problemas ") -> Identifica los tipos de bloqueos mentales mediante el análisis de casos y experiencias personales en situaciones que dificultan la resolución de problemas | C12: =IFERROR(__xludf.DUMMYFUNCTION("""COMPUTED_VALUE"""),"Unidad 1: La creatividad y bloqueos mentales") -> Unidad 1: La creatividad y bloqueos mentales | D12: =IFERROR(__xludf.DUMMYFUNCTION("""COMPUTED_VALUE"""),"La creatividad") -> La creatividad | E12: =IFERROR(__xludf.DUMMYFUNCTION("""COMPUTED_VALUE"""),"Técnicas para producir ideas") -> Técnicas para producir ideas | F12: No | G12: Sí
B13: =IFERROR(__xludf.DUMMYFUNCTION("""COMPUTED_VALUE"""),"Identifica los tipos de bloqueos mentales mediante el análisis de casos y experiencias personales en situaciones que dificultan la resolución de problemas ") -> Identifica los tipos de bloqueos mentales mediante el análisis de casos y experiencias personales en situaciones que dificultan la resolución de problemas | C13: =IFERROR(__xludf.DUMMYFUNCTION("""COMPUTED_VALUE"""),"Unidad 1: La creatividad y bloqueos mentales") -> Unidad 1: La creatividad y bloqueos mentales | D13: =IFERROR(__xludf.DUMMYFUNCTION("""COMPUTED_VALUE"""),"La creatividad") -> La creatividad | E13: =IFERROR(__xludf.DUMMYFUNCTION("""COMPUTED_VALUE"""),"Como hacer mas eficiente la mente") -> Como hacer mas eficiente la mente | F13: No | G13: Sí
B14: =IFERROR(__xludf.DUMMYFUNCTION("""COMPUTED_VALUE"""),"Identifica los tipos de bloqueos mentales mediante el análisis de casos y experiencias personales en situaciones que dificultan la resolución de problemas ") -> Identifica los tipos de bloqueos mentales mediante el análisis de casos y experiencias personales en situaciones que dificultan la resolución de problemas | C14: =IFERROR(__xludf.DUMMYFUNCTION("""COMPUTED_VALUE"""),"Unidad 1: La creatividad y bloqueos mentales") -> Unidad 1: La creatividad y bloqueos mentales | D14: =IFERROR(__xludf.DUMMYFUNCTION("""COMPUTED_VALUE"""),"La creatividad") -> La creatividad | E14: =IFERROR(__xludf.DUMMYFUNCTION("""COMPUTED_VALUE"""),"Método para ser más eficiente ") -> Método para ser más eficiente | F14: No | G14: Sí
B15: =IFERROR(__xludf.DUMMYFUNCTION("""COMPUTED_VALUE"""),"Identifica los tipos de bloqueos mentales mediante el análisis de casos y experiencias personales en situaciones que dificultan la resolución de problemas ") -> Identifica los tipos de bloqueos mentales mediante el análisis de casos y experiencias personales en situaciones que dificultan la resolución de problemas | C15: =IFERROR(__xludf.DUMMYFUNCTION("""COMPUTED_VALUE"""),"Unidad 1: La creatividad y bloqueos mentales") -> Unidad 1: La creatividad y bloqueos mentales | D15: =IFERROR(__xludf.DUMMYFUNCTION("""COMPUTED_VALUE"""),"Modelos Mentales") -> Modelos Mentales | E15: =IFERROR(__xludf.DUMMYFUNCTION("""COMPUTED_VALUE"""),"Bloqueos perceptivos") -> Bloqueos perceptivos | F15: No | G15: Sí
B16: =IFERROR(__xludf.DUMMYFUNCTION("""COMPUTED_VALUE"""),"Identifica los tipos de bloqueos mentales mediante el análisis de casos y experiencias personales en situaciones que dificultan la resolución de problemas ") -> Identifica los tipos de bloqueos mentales mediante el análisis de casos y experiencias personales en situaciones que dificultan la resolución de problemas | C16: =IFERROR(__xludf.DUMMYFUNCTION("""COMPUTED_VALUE"""),"Unidad 1: La creatividad y bloqueos mentales") -> Unidad 1: La creatividad y bloqueos mentales | D16: =IFERROR(__xludf.DUMMYFUNCTION("""COMPUTED_VALUE"""),"Modelos Mentales") -> Modelos Mentales | E16: =IFERROR(__xludf.DUMMYFUNCTION("""COMPUTED_VALUE"""),"Bloqueos emocionales") -> Bloqueos emocionales | F16: No | G16: Sí
B17: =IFERROR(__xludf.DUMMYFUNCTION("""COMPUTED_VALUE"""),"Identifica los tipos de bloqueos mentales mediante el análisis de casos y experiencias personales en situaciones que dificultan la resolución de problemas ") -> Identifica los tipos de bloqueos mentales mediante el análisis de casos y experiencias personales en situaciones que dificultan la resolución de problemas | C17: =IFERROR(__xludf.DUMMYFUNCTION("""COMPUTED_VALUE"""),"Unidad 1: La creatividad y bloqueos mentales") -> Unidad 1: La creatividad y bloqueos mentales | D17: =IFERROR(__xludf.DUMMYFUNCTION("""COMPUTED_VALUE"""),"Modelos Mentales") -> Modelos Mentales | E17: =IFERROR(__xludf.DUMMYFUNCTION("""COMPUTED_VALUE"""),"Bloqueos culturales") -> Bloqueos culturales | F17: No | G17: Sí
B18: =IFERROR(__xludf.DUMMYFUNCTION("""COMPUTED_VALUE"""),"Identifica los tipos de bloqueos mentales mediante el análisis de casos y experiencias personales en situaciones que dificultan la resolución de problemas ") -> Identifica los tipos de bloqueos mentales mediante el análisis de casos y experiencias personales en situaciones que dificultan la resolución de problemas | C18: =IFERROR(__xludf.DUMMYFUNCTION("""COMPUTED_VALUE"""),"Unidad 1: La creatividad y bloqueos mentales") -> Unidad 1: La creatividad y bloqueos mentales | D18: =IFERROR(__xludf.DUMMYFUNCTION("""COMPUTED_VALUE"""),"Modelos Mentales") -> Modelos Mentales | E18: =IFERROR(__xludf.DUMMYFUNCTION("""COMPUTED_VALUE"""),"Bloqueos ambientales") -> Bloqueos ambientales | F18: No | G18: Sí
B19: =IFERROR(__xludf.DUMMYFUNCTION("""COMPUTED_VALUE"""),"Identifica los tipos de bloqueos mentales mediante el análisis de casos y experiencias personales en situaciones que dificultan la resolución de problemas ") -> Identifica los tipos de bloqueos mentales mediante el análisis de casos y experiencias personales en situaciones que dificultan la resolución de problemas | C19: =IFERROR(__xludf.DUMMYFUNCTION("""COMPUTED_VALUE"""),"Unidad 1: La creatividad y bloqueos mentales") -> Unidad 1: La creatividad y bloqueos mentales | D19: =IFERROR(__xludf.DUMMYFUNCTION("""COMPUTED_VALUE"""),"Modelos Mentales") -> Modelos Mentales | E19: =IFERROR(__xludf.DUMMYFUNCTION("""COMPUTED_VALUE"""),"Bloqueos intelectuales") -> Bloqueos intelectuales | F19: No | G19: Sí
B20: =IFERROR(__xludf.DUMMYFUNCTION("""COMPUTED_VALUE"""),"Identifica los tipos de bloqueos mentales mediante el análisis de casos y experiencias personales en situaciones que dificultan la resolución de problemas ") -> Identifica los tipos de bloqueos mentales mediante el análisis de casos y experiencias personales en situaciones que dificultan la resolución de problemas | C20: =IFERROR(__xludf.DUMMYFUNCTION("""COMPUTED_VALUE"""),"Unidad 1: La creatividad y bloqueos mentales") -> Unidad 1: La creatividad y bloqueos mentales | D20: =IFERROR(__xludf.DUMMYFUNCTION("""COMPUTED_VALUE"""),"Modelos Mentales") -> Modelos Mentales | E20: =IFERROR(__xludf.DUMMYFUNCTION("""COMPUTED_VALUE"""),"Bloqueos expresivos") -> Bloqueos expresivos | F20: No | G20: Sí
B21: =IFERROR(__xludf.DUMMYFUNCTION("""COMPUTED_VALUE"""),"Reconoce los principios fundamentales de la lógica mediante el análisis de enunciados y situaciones cotidianas que permitan desarrollar habilidades de pensamiento crítico y razonamiento válido") -> Reconoce los principios fundamentales de la lógica mediante el análisis de enunciados y situaciones cotidianas que permitan desarrollar habilidades de pensamiento crítico y razonamiento válido | C21: =IFERROR(__xludf.DUMMYFUNCTION("""COMPUTED_VALUE"""),"Unidad 2: Lógica") -> Unidad 2: Lógica | D21: =IFERROR(__xludf.DUMMYFUNCTION("""COMPUTED_VALUE"""),"Lógica") -> Lógica | E21: =IFERROR(__xludf.DUMMYFUNCTION("""COMPUTED_VALUE"""),"Introducción a la Lógica") -> Introducción a la Lógica | F21: Sí | G21: Sí
B22: =IFERROR(__xludf.DUMMYFUNCTION("""COMPUTED_VALUE"""),"Reconoce los principios fundamentales de la lógica mediante el análisis de enunciados y situaciones cotidianas que permitan desarrollar habilidades de pensamiento crítico y razonamiento válido") -> Reconoce los principios fundamentales de la lógica mediante el análisis de enunciados y situaciones cotidianas que permitan desarrollar habilidades de pensamiento crítico y razonamiento válido | C22: =IFERROR(__xludf.DUMMYFUNCTION("""COMPUTED_VALUE"""),"Unidad 2: Lógica") -> Unidad 2: Lógica | D22: =IFERROR(__xludf.DUMMYFUNCTION("""COMPUTED_VALUE"""),"Lógica") -> Lógica | E22: =IFERROR(__xludf.DUMMYFUNCTION("""COMPUTED_VALUE"""),"Etimologia de la Lógica") -> Etimologia de la Lógica | F22: No | G22: Sí
B23: =IFERROR(__xludf.DUMMYFUNCTION("""COMPUTED_VALUE"""),"Reconoce los principios fundamentales de la lógica mediante el análisis de enunciados y situaciones cotidianas que permitan desarrollar habilidades de pensamiento crítico y razonamiento válido") -> Reconoce los principios fundamentales de la lógica mediante el análisis de enunciados y situaciones cotidianas que permitan desarrollar habilidades de pensamiento crítico y razonamiento válido | C23: =IFERROR(__xludf.DUMMYFUNCTION("""COMPUTED_VALUE"""),"Unidad 2: Lógica") -> Unidad 2: Lógica | D23: =IFERROR(__xludf.DUMMYFUNCTION("""COMPUTED_VALUE"""),"Lógica") -> Lógica | E23: =IFERROR(__xludf.DUMMYFUNCTION("""COMPUTED_VALUE"""),"Pensar y Razonar") -> Pensar y Razonar | F23: No | G23: Sí
B24: =IFERROR(__xludf.DUMMYFUNCTION("""COMPUTED_VALUE"""),"Reconoce los principios fundamentales de la lógica mediante el análisis de enunciados y situaciones cotidianas que permitan desarrollar habilidades de pensamiento crítico y razonamiento válido") -> Reconoce los principios fundamentales de la lógica mediante el análisis de enunciados y situaciones cotidianas que permitan desarrollar habilidades de pensamiento crítico y razonamiento válido | C24: =IFERROR(__xludf.DUMMYFUNCTION("""COMPUTED_VALUE"""),"Unidad 2: Lógica") -> Unidad 2: Lógica | D24: =IFERROR(__xludf.DUMMYFUNCTION("""COMPUTED_VALUE"""),"Lógica") -> Lógica | E24: =IFERROR(__xludf.DUMMYFUNCTION("""COMPUTED_VALUE"""),"Razonamiento Lógico") -> Razonamiento Lógico | F24: Sí | G24: Sí
B25: =IFERROR(__xludf.DUMMYFUNCTION("""COMPUTED_VALUE"""),"Reconoce los principios fundamentales de la lógica mediante el análisis de enunciados y situaciones cotidianas que permitan desarrollar habilidades de pensamiento crítico y razonamiento válido") -> Reconoce los principios fundamentales de la lógica mediante el análisis de enunciados y situaciones cotidianas que permitan desarrollar habilidades de pensamiento crítico y razonamiento válido | C25: =IFERROR(__xludf.DUMMYFUNCTION("""COMPUTED_VALUE"""),"Unidad 2: Lógica") -> Unidad 2: Lógica | D25: =IFERROR(__xludf.DUMMYFUNCTION("""COMPUTED_VALUE"""),"Lógica") -> Lógica | E25: =IFERROR(__xludf.DUMMYFUNCTION("""COMPUTED_VALUE"""),"Relación entre la Lógica y otras Ciencias") -> Relación entre la Lógica y otras Ciencias | F25: Sí | G25: Sí
B26: =IFERROR(__xludf.DUMMYFUNCTION("""COMPUTED_VALUE"""),"Reconoce los principios fundamentales de la lógica mediante el análisis de enunciados y situaciones cotidianas que permitan desarrollar habilidades de pensamiento crítico y razonamiento válido") -> Reconoce los principios fundamentales de la lógica mediante el análisis de enunciados y situaciones cotidianas que permitan desarrollar habilidades de pensamiento crítico y razonamiento válido | C26: =IFERROR(__xludf.DUMMYFUNCTION("""COMPUTED_VALUE"""),"Unidad 2: Lógica") -> Unidad 2: Lógica | D26: =IFERROR(__xludf.DUMMYFUNCTION("""COMPUTED_VALUE"""),"Lógica") -> Lógica | E26: =IFERROR(__xludf.DUMMYFUNCTION("""COMPUTED_VALUE"""),"Reduccionimo Lógico") -> Reduccionimo Lógico | F26: No | G26: Sí
B27: =IFERROR(__xludf.DUMMYFUNCTION("""COMPUTED_VALUE"""),"Reconoce los principios fundamentales de la lógica mediante el análisis de enunciados y situaciones cotidianas que permitan desarrollar habilidades de pensamiento crítico y razonamiento válido") -> Reconoce los principios fundamentales de la lógica mediante el análisis de enunciados y situaciones cotidianas que permitan desarrollar habilidades de pensamiento crítico y razonamiento válido | C27: =IFERROR(__xludf.DUMMYFUNCTION("""COMPUTED_VALUE"""),"Unidad 2: Lógica") -> Unidad 2: Lógica | D27: =IFERROR(__xludf.DUMMYFUNCTION("""COMPUTED_VALUE"""),"Lógica") -> Lógica | E27: =IFERROR(__xludf.DUMMYFUNCTION("""COMPUTED_VALUE"""),"Lógica y Psicología") -> Lógica y Psicología | F27: No | G27: Sí
B28: =IFERROR(__xludf.DUMMYFUNCTION("""COMPUTED_VALUE"""),"Reconoce los principios fundamentales de la lógica mediante el análisis de enunciados y situaciones cotidianas que permitan desarrollar habilidades de pensamiento crítico y razonamiento válido") -> Reconoce los principios fundamentales de la lógica mediante el análisis de enunciados y situaciones cotidianas que permitan desarrollar habilidades de pensamiento crítico y razonamiento válido | C28: =IFERROR(__xludf.DUMMYFUNCTION("""COMPUTED_VALUE"""),"Unidad 2: Lógica") -> Unidad 2: Lógica | D28: =IFERROR(__xludf.DUMMYFUNCTION("""COMPUTED_VALUE"""),"La Lógica y otras Ciencias") -> La Lógica y otras Ciencias | E28: =IFERROR(__xludf.DUMMYFUNCTION("""COMPUTED_VALUE"""),"Lógica y Sociología") -> Lógica y Sociología | F28: No | G28: Sí
B29: =IFERROR(__xludf.DUMMYFUNCTION("""COMPUTED_VALUE"""),"Reconoce los principios fundamentales de la lógica mediante el análisis de enunciados y situaciones cotidianas que permitan desarrollar habilidades de pensamiento crítico y razonamiento válido") -> Reconoce los principios fundamentales de la lógica mediante el análisis de enunciados y situaciones cotidianas que permitan desarrollar habilidades de pensamiento crítico y razonamiento válido | C29: =IFERROR(__xludf.DUMMYFUNCTION("""COMPUTED_VALUE"""),"Unidad 2: Lógica") -> Unidad 2: Lógica | D29: =IFERROR(__xludf.DUMMYFUNCTION("""COMPUTED_VALUE"""),"La Lógica y otras Ciencias") -> La Lógica y otras Ciencias | E29: =IFERROR(__xludf.DUMMYFUNCTION("""COMPUTED_VALUE"""),"Lógica y Matemáticas") -> Lógica y Matemáticas | F29: No | G29: Sí
B30: =IFERROR(__xludf.DUMMYFUNCTION("""COMPUTED_VALUE"""),"Reconoce los principios fundamentales de la lógica mediante el análisis de enunciados y situaciones cotidianas que permitan desarrollar habilidades de pensamiento crítico y razonamiento válido") -> Reconoce los principios fundamentales de la lógica mediante el análisis de enunciados y situaciones cotidianas que permitan desarrollar habilidades de pensamiento crítico y razonamiento válido | C30: =IFERROR(__xludf.DUMMYFUNCTION("""COMPUTED_VALUE"""),"Unidad 2: Lógica") -> Unidad 2: Lógica | D30: =IFERROR(__xludf.DUMMYFUNCTION("""COMPUTED_VALUE"""),"La Lógica y otras Ciencias") -> La Lógica y otras Ciencias | E30: =IFERROR(__xludf.DUMMYFUNCTION("""COMPUTED_VALUE"""),"Lógica y Gramática") -> Lógica y Gramática | F30: No | G30: Sí
B31: =IFERROR(__xludf.DUMMYFUNCTION("""COMPUTED_VALUE"""),"Reconoce los principios fundamentales de la lógica mediante el análisis de enunciados y situaciones cotidianas que permitan desarrollar habilidades de pensamiento crítico y razonamiento válido") -> Reconoce los principios fundamentales de la lógica mediante el análisis de enunciados y situaciones cotidianas que permitan desarrollar habilidades de pensamiento crítico y razonamiento válido | C31: =IFERROR(__xludf.DUMMYFUNCTION("""COMPUTED_VALUE"""),"Unidad 2: Lógica") -> Unidad 2: Lógica | D31: =IFERROR(__xludf.DUMMYFUNCTION("""COMPUTED_VALUE"""),"La Lógica y otras Ciencias") -> La Lógica y otras Ciencias | E31: =IFERROR(__xludf.DUMMYFUNCTION("""COMPUTED_VALUE"""),"Lógica y Filosofía") -> Lógica y Filosofía | F31: No | G31: Sí
B32: =IFERROR(__xludf.DUMMYFUNCTION("""COMPUTED_VALUE"""),"Reconoce los principios fundamentales de la lógica mediante el análisis de enunciados y situaciones cotidianas que permitan desarrollar habilidades de pensamiento crítico y razonamiento válido") -> Reconoce los principios fundamentales de la lógica mediante el análisis de enunciados y situaciones cotidianas que permitan desarrollar habilidades de pensamiento crítico y razonamiento válido | C32: =IFERROR(__xludf.DUMMYFUNCTION("""COMPUTED_VALUE"""),"Unidad 2: Lógica") -> Unidad 2: Lógica | D32: =IFERROR(__xludf.DUMMYFUNCTION("""COMPUTED_VALUE"""),"La Lógica y otras Ciencias") -> La Lógica y otras Ciencias | E32: =IFERROR(__xludf.DUMMYFUNCTION("""COMPUTED_VALUE"""),"Definición de la Lógica como Ciencia") -> Definición de la Lógica como Ciencia | F32: Sí | G32: Sí
B33: =IFERROR(__xludf.DUMMYFUNCTION("""COMPUTED_VALUE"""),"Reconoce los principios fundamentales de la lógica mediante el análisis de enunciados y situaciones cotidianas que permitan desarrollar habilidades de pensamiento crítico y razonamiento válido") -> Reconoce los principios fundamentales de la lógica mediante el análisis de enunciados y situaciones cotidianas que permitan desarrollar habilidades de pensamiento crítico y razonamiento válido | C33: =IFERROR(__xludf.DUMMYFUNCTION("""COMPUTED_VALUE"""),"Unidad 2: Lógica") -> Unidad 2: Lógica | D33: =IFERROR(__xludf.DUMMYFUNCTION("""COMPUTED_VALUE"""),"La Lógica y otras Ciencias") -> La Lógica y otras Ciencias | E33: =IFERROR(__xludf.DUMMYFUNCTION("""COMPUTED_VALUE"""),"Estructura Fundamental de la Lógica") -> Estructura Fundamental de la Lógica | F33: No | G33: Sí
B34: =IFERROR(__xludf.DUMMYFUNCTION("""COMPUTED_VALUE"""),"Reconoce los principios fundamentales de la lógica mediante el análisis de enunciados y situaciones cotidianas que permitan desarrollar habilidades de pensamiento crítico y razonamiento válido") -> Reconoce los principios fundamentales de la lógica mediante el análisis de enunciados y situaciones cotidianas que permitan desarrollar habilidades de pensamiento crítico y razonamiento válido | C34: =IFERROR(__xludf.DUMMYFUNCTION("""COMPUTED_VALUE"""),"Unidad 2: Lógica") -> Unidad 2: Lógica | D34: =IFERROR(__xludf.DUMMYFUNCTION("""COMPUTED_VALUE"""),"La Lógica y otras Ciencias") -> La Lógica y otras Ciencias | E34: =IFERROR(__xludf.DUMMYFUNCTION("""COMPUTED_VALUE"""),"La Apofántica") -> La Apofántica | F34: No | G34: Sí
B35: =IFERROR(__xludf.DUMMYFUNCTION("""COMPUTED_VALUE"""),"Identifica los tipos de bloqueos mentales mediante el análisis de casos y experiencias personales en situaciones que dificultan la resolución de problemas ") -> Identifica los tipos de bloqueos mentales mediante el análisis de casos y experiencias personales en situaciones que dificultan la resolución de problemas | C35: =IFERROR(__xludf.DUMMYFUNCTION("""COMPUTED_VALUE"""),"Primer Parcial Unidad 1 y 2") -> Primer Parcial Unidad 1 y 2 | D35: =IFERROR(__xludf.DUMMYFUNCTION("""COMPUTED_VALUE"""),"Primer Parcial Unidad 1 y 2") -> Primer Parcial Unidad 1 y 2 | E35: =IFERROR(__xludf.DUMMYFUNCTION("""COMPUTED_VALUE"""),"Pasos en la resolución de problemas") -> Pasos en la resolución de problemas | F35: No | G35: Sí
B36: =IFERROR(__xludf.DUMMYFUNCTION("""COMPUTED_VALUE"""),"Identifica los tipos de bloqueos mentales mediante el análisis de casos y experiencias personales en situaciones que dificultan la resolución de problemas ") -> Identifica los tipos de bloqueos mentales mediante el análisis de casos y experiencias personales en situaciones que dificultan la resolución de problemas | C36: =IFERROR(__xludf.DUMMYFUNCTION("""COMPUTED_VALUE"""),"Primer Parcial Unidad 1 y 2") -> Primer Parcial Unidad 1 y 2 | D36: =IFERROR(__xludf.DUMMYFUNCTION("""COMPUTED_VALUE"""),"Primer Parcial Unidad 1 y 2") -> Primer Parcial Unidad 1 y 2 | E36: =IFERROR(__xludf.DUMMYFUNCTION("""COMPUTED_VALUE"""),"Técnicas para producir ideas") -> Técnicas para producir ideas | F36: No | G36: Sí
B37: =IFERROR(__xludf.DUMMYFUNCTION("""COMPUTED_VALUE"""),"Identifica los tipos de bloqueos mentales mediante el análisis de casos y experiencias personales en situaciones que dificultan la resolución de problemas ") -> Identifica los tipos de bloqueos mentales mediante el análisis de casos y experiencias personales en situaciones que dificultan la resolución de problemas | C37: =IFERROR(__xludf.DUMMYFUNCTION("""COMPUTED_VALUE"""),"Primer Parcial Unidad 1 y 2") -> Primer Parcial Unidad 1 y 2 | D37: =IFERROR(__xludf.DUMMYFUNCTION("""COMPUTED_VALUE"""),"Primer Parcial Unidad 1 y 2") -> Primer Parcial Unidad 1 y 2 | E37: =IFERROR(__xludf.DUMMYFUNCTION("""COMPUTED_VALUE"""),"Método para ser más eficiente ") -> Método para ser más eficiente | F37: No | G37: Sí
B38: =IFERROR(__xludf.DUMMYFUNCTION("""COMPUTED_VALUE"""),"Identifica los tipos de bloqueos mentales mediante el análisis de casos y experiencias personales en situaciones que dificultan la resolución de problemas ") -> Identifica los tipos de bloqueos mentales mediante el análisis de casos y experiencias personales en situaciones que dificultan la resolución de problemas | C38: =IFERROR(__xludf.DUMMYFUNCTION("""COMPUTED_VALUE"""),"Primer Parcial Unidad 1 y 2") -> Primer Parcial Unidad 1 y 2 | D38: =IFERROR(__xludf.DUMMYFUNCTION("""COMPUTED_VALUE"""),"Primer Parcial Unidad 1 y 2") -> Primer Parcial Unidad 1 y 2 | E38: =IFERROR(__xludf.DUMMYFUNCTION("""COMPUTED_VALUE"""),"Bloqueos mentales") -> Bloqueos mentales | F38: No | G38: Sí
B39: =IFERROR(__xludf.DUMMYFUNCTION("""COMPUTED_VALUE"""),"Reconoce los principios fundamentales de la lógica mediante el análisis de enunciados y situaciones cotidianas que permitan desarrollar habilidades de pensamiento crítico y razonamiento válido") -> Reconoce los principios fundamentales de la lógica mediante el análisis de enunciados y situaciones cotidianas que permitan desarrollar habilidades de pensamiento crítico y razonamiento válido | C39: =IFERROR(__xludf.DUMMYFUNCTION("""COMPUTED_VALUE"""),"Primer Parcial Unidad 1 y 2") -> Primer Parcial Unidad 1 y 2 | D39: =IFERROR(__xludf.DUMMYFUNCTION("""COMPUTED_VALUE"""),"Primer Parcial Unidad 1 y 2") -> Primer Parcial Unidad 1 y 2 | E39: =IFERROR(__xludf.DUMMYFUNCTION("""COMPUTED_VALUE"""),"Introducción a la Lógica") -> Introducción a la Lógica | F39: No | G39: Sí
B40: =IFERROR(__xludf.DUMMYFUNCTION("""COMPUTED_VALUE"""),"Reconoce los principios fundamentales de la lógica mediante el análisis de enunciados y situaciones cotidianas que permitan desarrollar habilidades de pensamiento crítico y razonamiento válido") -> Reconoce los principios fundamentales de la lógica mediante el análisis de enunciados y situaciones cotidianas que permitan desarrollar habilidades de pensamiento crítico y razonamiento válido | C40: =IFERROR(__xludf.DUMMYFUNCTION("""COMPUTED_VALUE"""),"Primer Parcial Unidad 1 y 2") -> Primer Parcial Unidad 1 y 2 | D40: =IFERROR(__xludf.DUMMYFUNCTION("""COMPUTED_VALUE"""),"Primer Parcial Unidad 1 y 2") -> Primer Parcial Unidad 1 y 2 | E40: =IFERROR(__xludf.DUMMYFUNCTION("""COMPUTED_VALUE"""),"Razonamiento Lógico") -> Razonamiento Lógico | F40: No | G40: Sí
B41: =IFERROR(__xludf.DUMMYFUNCTION("""COMPUTED_VALUE"""),"Reconoce los principios fundamentales de la lógica mediante el análisis de enunciados y situaciones cotidianas que permitan desarrollar habilidades de pensamiento crítico y razonamiento válido") -> Reconoce los principios fundamentales de la lógica mediante el análisis de enunciados y situaciones cotidianas que permitan desarrollar habilidades de pensamiento crítico y razonamiento válido | C41: =IFERROR(__xludf.DUMMYFUNCTION("""COMPUTED_VALUE"""),"Primer Parcial Unidad 1 y 2") -> Primer Parcial Unidad 1 y 2 | D41: =IFERROR(__xludf.DUMMYFUNCTION("""COMPUTED_VALUE"""),"Primer Parcial Unidad 1 y 2") -> Primer Parcial Unidad 1 y 2 | E41: =IFERROR(__xludf.DUMMYFUNCTION("""COMPUTED_VALUE"""),"Definición de la Lógica como Ciencia") -> Definición de la Lógica como Ciencia | F41: No | G41: Sí
...

Sheet Diseño_Lab_Post
B1: Que se impartio el en Curso Posterior el Segundo Semestre 2025
B3: Nombre del Curso | C3: Introducción a la Programación y Computación 2
B4: Codigo del Curso | C4: {=IFERROR(_xlfn.XLOOKUP(TRIM(C3), Competencias_actuales!L15:L1000, Competencias_actuales!K15:K1000), "Código no encontrado")} -> 771 | H4: =C4&" - "&C3 -> 771 - Introducción a la Programación y Computación 2
B6: No | C6: Competencia | D6: Unidad | E6: Tema | F6: Subtema | G6: Mes | H6: Semana
B7: =IFERROR(__xludf.DUMMYFUNCTION("QUERY(IMPORTRANGE(VLOOKUP(H4,METADA!A:B,2,FALSE), ""Diseño Curricular!A4:G500""), )"),1.0) -> 1 | C7: =IFERROR(__xludf.DUMMYFUNCTION("""COMPUTED_VALUE"""),"Aplica estructuras de control y funciones mediante programación básica en Python. para desarrollar algoritmos que resuelvan problemas. ") -> Aplica estructuras de control y funciones mediante programación básica en Python. para desarrollar algoritmos que resuelvan problemas. | D7: =IFERROR(__xludf.DUMMYFUNCTION("""COMPUTED_VALUE"""),"1. Introducción a Python") -> 1. Introducción a Python | E7: =IFERROR(__xludf.DUMMYFUNCTION("""COMPUTED_VALUE"""),"Introducción y Presentación") -> Introducción y Presentación | F7: =IFERROR(__xludf.DUMMYFUNCTION("""COMPUTED_VALUE"""),"Instalación de Python 3.X.X") -> Instalación de Python 3.X.X | G7: =IFERROR(__xludf.DUMMYFUNCTION("""COMPUTED_VALUE"""),"Julio") -> Julio | H7: =IFERROR(__xludf.DUMMYFUNCTION("""COMPUTED_VALUE"""),1.0) -> 1
B8: =IFERROR(__xludf.DUMMYFUNCTION("""COMPUTED_VALUE"""),2.0) -> 2 | C8: =IFERROR(__xludf.DUMMYFUNCTION("""COMPUTED_VALUE"""),"Aplica estructuras de control y funciones mediante programación básica en Python. para desarrollar algoritmos que resuelvan problemas. ") -> Aplica estructuras de control y funciones mediante programación básica en Python. para desarrollar algoritmos que resuelvan problemas. | D8: =IFERROR(__xludf.DUMMYFUNCTION("""COMPUTED_VALUE"""),"1. Introducción a Python") -> 1. Introducción a Python | E8: =IFERROR(__xludf.DUMMYFUNCTION("""COMPUTED_VALUE"""),"Introducción y Presentación") -> Introducción y Presentación | F8: =IFERROR(__xludf.DUMMYFUNCTION("""COMPUTED_VALUE"""),"Instalación del entorno de desarrollo") -> Instalación del entorno de desarrollo | G8: =IFERROR(__xludf.DUMMYFUNCTION("""COMPUTED_VALUE"""),"Julio") -> Julio | H8: =IFERROR(__xludf.DUMMYFUNCTION("""COMPUTED_VALUE"""),1.0) -> 1
B9: =IFERROR(__xludf.DUMMYFUNCTION("""COMPUTED_VALUE"""),3.0) -> 3 | C9: =IFERROR(__xludf.DUMMYFUNCTION("""COMPUTED_VALUE"""),"Aplica estructuras de control y funciones mediante programación básica en Python. para desarrollar algoritmos que resuelvan problemas. ") -> Aplica estructuras de control y funciones mediante programación básica en Python. para desarrollar algoritmos que resuelvan problemas. | D9: =IFERROR(__xludf.DUMMYFUNCTION("""COMPUTED_VALUE"""),"1. Introducción a Python") -> 1. Introducción a Python | E9: =IFERROR(__xludf.DUMMYFUNCTION("""COMPUTED_VALUE"""),"Introducción y Presentación") -> Introducción y Presentación | F9: =IFERROR(__xludf.DUMMYFUNCTION("""COMPUTED_VALUE"""),"Variables, Expresiones y sentencias") -> Variables, Expresiones y sentencias | G9: =IFERROR(__xludf.DUMMYFUNCTION("""COMPUTED_VALUE"""),"Julio") -> Julio | H9: =IFERROR(__xludf.DUMMYFUNCTION("""COMPUTED_VALUE"""),1.0) -> 1
B10: =IFERROR(__xludf.DUMMYFUNCTION("""COMPUTED_VALUE"""),4.0) -> 4 | C10: =IFERROR(__xludf.DUMMYFUNCTION("""COMPUTED_VALUE"""),"Aplica estructuras de control y funciones mediante programación básica en Python. para desarrollar algoritmos que resuelvan problemas. ") -> Aplica estructuras de control y funciones mediante programación básica en Python. para desarrollar algoritmos que resuelvan problemas. | D10: =IFERROR(__xludf.DUMMYFUNCTION("""COMPUTED_VALUE"""),"1. Introducción a Python") -> 1. Introducción a Python | E10: =IFERROR(__xludf.DUMMYFUNCTION("""COMPUTED_VALUE"""),"Introducción y Presentación") -> Introducción y Presentación | F10: =IFERROR(__xludf.DUMMYFUNCTION("""COMPUTED_VALUE"""),"Ejecuciones condicionales") -> Ejecuciones condicionales | G10: =IFERROR(__xludf.DUMMYFUNCTION("""COMPUTED_VALUE"""),"Julio") -> Julio | H10: =IFERROR(__xludf.DUMMYFUNCTION("""COMPUTED_VALUE"""),1.0) -> 1
B11: =IFERROR(__xludf.DUMMYFUNCTION("""COMPUTED_VALUE"""),5.0) -> 5 | C11: =IFERROR(__xludf.DUMMYFUNCTION("""COMPUTED_VALUE"""),"Aplica estructuras de control y funciones mediante programación básica en Python. para desarrollar algoritmos que resuelvan problemas. ") -> Aplica estructuras de control y funciones mediante programación básica en Python. para desarrollar algoritmos que resuelvan problemas. | D11: =IFERROR(__xludf.DUMMYFUNCTION("""COMPUTED_VALUE"""),"1. Introducción a Python") -> 1. Introducción a Python | E11: =IFERROR(__xludf.DUMMYFUNCTION("""COMPUTED_VALUE"""),"Introducción y Presentación") -> Introducción y Presentación | F11: =IFERROR(__xludf.DUMMYFUNCTION("""COMPUTED_VALUE"""),"Funciones") -> Funciones | G11: =IFERROR(__xludf.DUMMYFUNCTION("""COMPUTED_VALUE"""),"Julio") -> Julio | H11: =IFERROR(__xludf.DUMMYFUNCTION("""COMPUTED_VALUE"""),1.0) -> 1
B12: =IFERROR(__xludf.DUMMYFUNCTION("""COMPUTED_VALUE"""),6.0) -> 6 | C12: =IFERROR(__xludf.DUMMYFUNCTION("""COMPUTED_VALUE"""),"Aplica estructuras de control y funciones mediante programación básica en Python. para desarrollar algoritmos que resuelvan problemas. ") -> Aplica estructuras de control y funciones mediante programación básica en Python. para desarrollar algoritmos que resuelvan problemas. | D12: =IFERROR(__xludf.DUMMYFUNCTION("""COMPUTED_VALUE"""),"1. Introducción a Python") -> 1. Introducción a Python | E12: =IFERROR(__xludf.DUMMYFUNCTION("""COMPUTED_VALUE"""),"Introducción y Presentación") -> Introducción y Presentación | F12: =IFERROR(__xludf.DUMMYFUNCTION("""COMPUTED_VALUE"""),"Iteración") -> Iteración | G12: =IFERROR(__xludf.DUMMYFUNCTION("""COMPUTED_VALUE"""),"Julio") -> Julio | H12: =IFERROR(__xludf.DUMMYFUNCTION("""COMPUTED_VALUE"""),1.0) -> 1
B13: =IFERROR(__xludf.DUMMYFUNCTION("""COMPUTED_VALUE"""),7.0) -> 7 | C13: =IFERROR(__xludf.DUMMYFUNCTION("""COMPUTED_VALUE"""),"Aplica estructuras de control y funciones mediante programación básica en Python. para desarrollar algoritmos que resuelvan problemas. ") -> Aplica estructuras de control y funciones mediante programación básica en Python. para desarrollar algoritmos que resuelvan problemas. | D13: =IFERROR(__xludf.DUMMYFUNCTION("""COMPUTED_VALUE"""),"1. Introducción a Python") -> 1. Introducción a Python | E13: =IFERROR(__xludf.DUMMYFUNCTION("""COMPUTED_VALUE"""),"Introducción y Presentación") -> Introducción y Presentación | F13: =IFERROR(__xludf.DUMMYFUNCTION("""COMPUTED_VALUE"""),"Strings") -> Strings | G13: =IFERROR(__xludf.DUMMYFUNCTION("""COMPUTED_VALUE"""),"Julio") -> Julio | H13: =IFERROR(__xludf.DUMMYFUNCTION("""COMPUTED_VALUE"""),1.0) -> 1
B14: =IFERROR(__xludf.DUMMYFUNCTION("""COMPUTED_VALUE"""),8.0) -> 8 | C14: =IFERROR(__xludf.DUMMYFUNCTION("""COMPUTED_VALUE"""),"Aplica estructuras de control y funciones mediante programación básica en Python. para desarrollar algoritmos que resuelvan problemas. ") -> Aplica estructuras de control y funciones mediante programación básica en Python. para desarrollar algoritmos que resuelvan problemas. | D14: =IFERROR(__xludf.DUMMYFUNCTION("""COMPUTED_VALUE"""),"1. Introducción a Python") -> 1. Introducción a Python | E14: =IFERROR(__xludf.DUMMYFUNCTION("""COMPUTED_VALUE"""),"Programación Orientada a Objetos en Python") -> Programación Orientada a Objetos en Python | F14: =IFERROR(__xludf.DUMMYFUNCTION("""COMPUTED_VALUE"""),"Introducción al paradigma de POO") -> Introducción al paradigma de POO | G14: =IFERROR(__xludf.DUMMYFUNCTION("""COMPUTED_VALUE"""),"Julio") -> Julio | H14: =IFERROR(__xludf.DUMMYFUNCTION("""COMPUTED_VALUE"""),2.0) -> 2
B15: =IFERROR(__xludf.DUMMYFUNCTION("""COMPUTED_VALUE"""),9.0) -> 9 | C15: =IFERROR(__xludf.DUMMYFUNCTION("""COMPUTED_VALUE"""),"Aplica estructuras de control y funciones mediante programación básica en Python. para desarrollar algoritmos que resuelvan problemas. ") -> Aplica estructuras de control y funciones mediante programación básica en Python. para desarrollar algoritmos que resuelvan problemas. | D15: =IFERROR(__xludf.DUMMYFUNCTION("""COMPUTED_VALUE"""),"1. Introducción a Python") -> 1. Introducción a Python | E15: =IFERROR(__xludf.DUMMYFUNCTION("""COMPUTED_VALUE"""),"Programación Orientada a Objetos en Python") -> Programación Orientada a Objetos en Python | F15: =IFERROR(__xludf.DUMMYFUNCTION("""COMPUTED_VALUE"""),"Clases y Objetos(Métodos y Atributos)") -> Clases y Objetos(Métodos y Atributos) | G15: =IFERROR(__xludf.DUMMYFUNCTION("""COMPUTED_VALUE"""),"Julio") -> Julio | H15: =IFERROR(__xludf.DUMMYFUNCTION("""COMPUTED_VALUE"""),2.0) -> 2
B16: =IFERROR(__xludf.DUMMYFUNCTION("""COMPUTED_VALUE"""),10.0) -> 10 | C16: =IFERROR(__xludf.DUMMYFUNCTION("""COMPUTED_VALUE"""),"Aplica estructuras de control y funciones mediante programación básica en Python. para desarrollar algoritmos que resuelvan problemas. ") -> Aplica estructuras de control y funciones mediante programación básica en Python. para desarrollar algoritmos que resuelvan problemas. | D16: =IFERROR(__xludf.DUMMYFUNCTION("""COMPUTED_VALUE"""),"1. Introducción a Python") -> 1. Introducción a Python | E16: =IFERROR(__xludf.DUMMYFUNCTION("""COMPUTED_VALUE"""),"Programación Orientada a Objetos en Python") -> Programación Orientada a Objetos en Python | F16: =IFERROR(__xludf.DUMMYFUNCTION("""COMPUTED_VALUE"""),"Pilares de la POO (Herencia, Abstracción, Polimosfismo, Encapsulamiento)") -> Pilares de la POO (Herencia, Abstracción, Polimosfismo, Encapsulamiento) | G16: =IFERROR(__xludf.DUMMYFUNCTION("""COMPUTED_VALUE"""),"Julio") -> Julio | H16: =IFERROR(__xludf.DUMMYFUNCTION("""COMPUTED_VALUE"""),2.0) -> 2
B17: =IFERROR(__xludf.DUMMYFUNCTION("""COMPUTED_VALUE"""),11.0) -> 11 | C17: =IFERROR(__xludf.DUMMYFUNCTION("""COMPUTED_VALUE"""),"Aplica técnicas de control de versiones, como Git Flow, branching, merging y versionamiento semántico en GIT para asegurar la calidad del software mediante un historial de cambios estructurado. ") -> Aplica técnicas de control de versiones, como Git Flow, branching, merging y versionamiento semántico en GIT para asegurar la calidad del software mediante un historial de cambios estructurado. | D17: =IFERROR(__xludf.DUMMYFUNCTION("""COMPUTED_VALUE"""),"2. Manejo de versiones") -> 2. Manejo de versiones | E17: =IFERROR(__xludf.DUMMYFUNCTION("""COMPUTED_VALUE"""),"Git Workflow") -> Git Workflow | F17: =IFERROR(__xludf.DUMMYFUNCTION("""COMPUTED_VALUE"""),"Introducción a GIT y Control de versiones") -> Introducción a GIT y Control de versiones | G17: =IFERROR(__xludf.DUMMYFUNCTION("""COMPUTED_VALUE"""),"Agosto") -> Agosto | H17: =IFERROR(__xludf.DUMMYFUNCTION("""COMPUTED_VALUE"""),2.0) -> 2
B18: =IFERROR(__xludf.DUMMYFUNCTION("""COMPUTED_VALUE"""),12.0) -> 12 | C18: =IFERROR(__xludf.DUMMYFUNCTION("""COMPUTED_VALUE"""),"Aplica técnicas de control de versiones, como Git Flow, branching, merging y versionamiento semántico en GIT para asegurar la calidad del software mediante un historial de cambios estructurado. ") -> Aplica técnicas de control de versiones, como Git Flow, branching, merging y versionamiento semántico en GIT para asegurar la calidad del software mediante un historial de cambios estructurado. | D18: =IFERROR(__xludf.DUMMYFUNCTION("""COMPUTED_VALUE"""),"2. Manejo de versiones") -> 2. Manejo de versiones | E18: =IFERROR(__xludf.DUMMYFUNCTION("""COMPUTED_VALUE"""),"Git Workflow") -> Git Workflow | F18: =IFERROR(__xludf.DUMMYFUNCTION("""COMPUTED_VALUE"""),"Fundamentos de control de versiones con Git y su Configuracion Inicial para el versionamiento de proyectos") -> Fundamentos de control de versiones con Git y su Configuracion Inicial para el versionamiento de proyectos | G18: =IFERROR(__xludf.DUMMYFUNCTION("""COMPUTED_VALUE"""),"Agosto") -> Agosto | H18: =IFERROR(__xludf.DUMMYFUNCTION("""COMPUTED_VALUE"""),2.0) -> 2
B19: =IFERROR(__xludf.DUMMYFUNCTION("""COMPUTED_VALUE"""),13.0) -> 13 | C19: =IFERROR(__xludf.DUMMYFUNCTION("""COMPUTED_VALUE"""),"Aplica técnicas de control de versiones, como Git Flow, branching, merging y versionamiento semántico en GIT para asegurar la calidad del software mediante un historial de cambios estructurado. ") -> Aplica técnicas de control de versiones, como Git Flow, branching, merging y versionamiento semántico en GIT para asegurar la calidad del software mediante un historial de cambios estructurado. | D19: =IFERROR(__xludf.DUMMYFUNCTION("""COMPUTED_VALUE"""),"2. Manejo de versiones") -> 2. Manejo de versiones | E19: =IFERROR(__xludf.DUMMYFUNCTION("""COMPUTED_VALUE"""),"Git Workflow") -> Git Workflow | F19: =IFERROR(__xludf.DUMMYFUNCTION("""COMPUTED_VALUE"""),"Git Flow: Implementación de Troncales y Ramas") -> Git Flow: Implementación de Troncales y Ramas | G19: =IFERROR(__xludf.DUMMYFUNCTION("""COMPUTED_VALUE"""),"Agosto") -> Agosto | H19: =IFERROR(__xludf.DUMMYFUNCTION("""COMPUTED_VALUE"""),2.0) -> 2
B20: =IFERROR(__xludf.DUMMYFUNCTION("""COMPUTED_VALUE"""),14.0) -> 14 | C20: =IFERROR(__xludf.DUMMYFUNCTION("""COMPUTED_VALUE"""),"Aplica técnicas de control de versiones, como Git Flow, branching, merging y versionamiento semántico en GIT para asegurar la calidad del software mediante un historial de cambios estructurado. ") -> Aplica técnicas de control de versiones, como Git Flow, branching, merging y versionamiento semántico en GIT para asegurar la calidad del software mediante un historial de cambios estructurado. | D20: =IFERROR(__xludf.DUMMYFUNCTION("""COMPUTED_VALUE"""),"2. Manejo de versiones") -> 2. Manejo de versiones | E20: =IFERROR(__xludf.DUMMYFUNCTION("""COMPUTED_VALUE"""),"Git Workflow") -> Git Workflow | F20: =IFERROR(__xludf.DUMMYFUNCTION("""COMPUTED_VALUE"""),"Branching, Merging y Utilización de Etiquetas (Tags) en Git") -> Branching, Merging y Utilización de Etiquetas (Tags) en Git | G20: =IFERROR(__xludf.DUMMYFUNCTION("""COMPUTED_VALUE"""),"Agosto") -> Agosto | H20: =IFERROR(__xludf.DUMMYFUNCTION("""COMPUTED_VALUE"""),2.0) -> 2
B21: =IFERROR(__xludf.DUMMYFUNCTION("""COMPUTED_VALUE"""),15.0) -> 15 | C21: =IFERROR(__xludf.DUMMYFUNCTION("""COMPUTED_VALUE"""),"Analiza actividades en archivos XML utilizando técnicas de lectura estructurada para identificar y extraer información relevante. ") -> Analiza actividades en archivos XML utilizando técnicas de lectura estructurada para identificar y extraer información relevante. | D21: =IFERROR(__xludf.DUMMYFUNCTION("""COMPUTED_VALUE"""),"3. Procesamiento de datos XML") -> 3. Procesamiento de datos XML | E21: =IFERROR(__xludf.DUMMYFUNCTION("""COMPUTED_VALUE"""),"Lectura de actividades y XML") -> Lectura de actividades y XML | F21: =IFERROR(__xludf.DUMMYFUNCTION("""COMPUTED_VALUE"""),"Introducción a bases de XML") -> Introducción a bases de XML | G21: =IFERROR(__xludf.DUMMYFUNCTION("""COMPUTED_VALUE"""),"Agosto") -> Agosto | H21: =IFERROR(__xludf.DUMMYFUNCTION("""COMPUTED_VALUE"""),3.0) -> 3
B22: =IFERROR(__xludf.DUMMYFUNCTION("""COMPUTED_VALUE"""),16.0) -> 16 | C22: =IFERROR(__xludf.DUMMYFUNCTION("""COMPUTED_VALUE"""),"Analiza actividades en archivos XML utilizando técnicas de lectura estructurada para identificar y extraer información relevante. ") -> Analiza actividades en archivos XML utilizando técnicas de lectura estructurada para identificar y extraer información relevante. | D22: =IFERROR(__xludf.DUMMYFUNCTION("""COMPUTED_VALUE"""),"3. Procesamiento de datos XML") -> 3. Procesamiento de datos XML | E22: =IFERROR(__xludf.DUMMYFUNCTION("""COMPUTED_VALUE"""),"Lectura de actividades y XML") -> Lectura de actividades y XML | F22: =IFERROR(__xludf.DUMMYFUNCTION("""COMPUTED_VALUE"""),"Procesamiento de datos con libreria DOM") -> Procesamiento de datos con libreria DOM | G22: =IFERROR(__xludf.DUMMYFUNCTION("""COMPUTED_VALUE"""),"Agosto") -> Agosto | H22: =IFERROR(__xludf.DUMMYFUNCTION("""COMPUTED_VALUE"""),3.0) -> 3
B23: =IFERROR(__xludf.DUMMYFUNCTION("""COMPUTED_VALUE"""),17.0) -> 17 | C23: =IFERROR(__xludf.DUMMYFUNCTION("""COMPUTED_VALUE"""),"Analiza actividades en archivos XML utilizando técnicas de lectura estructurada para identificar y extraer información relevante. ") -> Analiza actividades en archivos XML utilizando técnicas de lectura estructurada para identificar y extraer información relevante. | D23: =IFERROR(__xludf.DUMMYFUNCTION("""COMPUTED_VALUE"""),"3. Procesamiento de datos XML") -> 3. Procesamiento de datos XML | E23: =IFERROR(__xludf.DUMMYFUNCTION("""COMPUTED_VALUE"""),"Lectura de actividades y XML") -> Lectura de actividades y XML | F23: =IFERROR(__xludf.DUMMYFUNCTION("""COMPUTED_VALUE"""),"Procesamiento de datos con libreria ElemntTree") -> Procesamiento de datos con libreria ElemntTree | G23: =IFERROR(__xludf.DUMMYFUNCTION("""COMPUTED_VALUE"""),"Agosto") -> Agosto | H23: =IFERROR(__xludf.DUMMYFUNCTION("""COMPUTED_VALUE"""),3.0) -> 3
B24: =IFERROR(__xludf.DUMMYFUNCTION("""COMPUTED_VALUE"""),18.0) -> 18 | C24: =IFERROR(__xludf.DUMMYFUNCTION("""COMPUTED_VALUE"""),"Analiza actividades en archivos XML utilizando técnicas de lectura estructurada para identificar y extraer información relevante. ") -> Analiza actividades en archivos XML utilizando técnicas de lectura estructurada para identificar y extraer información relevante. | D24: =IFERROR(__xludf.DUMMYFUNCTION("""COMPUTED_VALUE"""),"3. Procesamiento de datos XML") -> 3. Procesamiento de datos XML | E24: =IFERROR(__xludf.DUMMYFUNCTION("""COMPUTED_VALUE"""),"Lectura de actividades y XML") -> Lectura de actividades y XML | F24: =IFERROR(__xludf.DUMMYFUNCTION("""COMPUTED_VALUE"""),"Introduccion Xpath") -> Introduccion Xpath | G24: =IFERROR(__xludf.DUMMYFUNCTION("""COMPUTED_VALUE"""),"Agosto") -> Agosto | H24: =IFERROR(__xludf.DUMMYFUNCTION("""COMPUTED_VALUE"""),3.0) -> 3
B25: =IFERROR(__xludf.DUMMYFUNCTION("""COMPUTED_VALUE"""),19.0) -> 19 | C25: =IFERROR(__xludf.DUMMYFUNCTION("""COMPUTED_VALUE"""),"Analiza actividades en archivos XML utilizando técnicas de lectura estructurada para identificar y extraer información relevante. ") -> Analiza actividades en archivos XML utilizando técnicas de lectura estructurada para identificar y extraer información relevante. | D25: =IFERROR(__xludf.DUMMYFUNCTION("""COMPUTED_VALUE"""),"3. Procesamiento de datos XML") -> 3. Procesamiento de datos XML | E25: =IFERROR(__xludf.DUMMYFUNCTION("""COMPUTED_VALUE"""),"Lectura de actividades y XML") -> Lectura de actividades y XML | F25: =IFERROR(__xludf.DUMMYFUNCTION("""COMPUTED_VALUE"""),"Procesamiento de datos con libreria Xpath") -> Procesamiento de datos con libreria Xpath | G25: =IFERROR(__xludf.DUMMYFUNCTION("""COMPUTED_VALUE"""),"Agosto") -> Agosto | H25: =IFERROR(__xludf.DUMMYFUNCTION("""COMPUTED_VALUE"""),3.0) -> 3
